[2021-08-10 15:42:57,070] {taskinstance.py:670} INFO - Dependencies all met for <TaskInstance: twitter_dag.twitter_aluraonline 2021-08-04T09:00:00+00:00 [queued]>
[2021-08-10 15:42:57,079] {taskinstance.py:670} INFO - Dependencies all met for <TaskInstance: twitter_dag.twitter_aluraonline 2021-08-04T09:00:00+00:00 [queued]>
[2021-08-10 15:42:57,079] {taskinstance.py:880} INFO - 
--------------------------------------------------------------------------------
[2021-08-10 15:42:57,079] {taskinstance.py:881} INFO - Starting attempt 2 of 2
[2021-08-10 15:42:57,079] {taskinstance.py:882} INFO - 
--------------------------------------------------------------------------------
[2021-08-10 15:42:57,089] {taskinstance.py:901} INFO - Executing <Task(TwitterOperator): twitter_aluraonline> on 2021-08-04T09:00:00+00:00
[2021-08-10 15:42:57,091] {standard_task_runner.py:54} INFO - Started process 11506 to run task
[2021-08-10 15:42:57,194] {standard_task_runner.py:77} INFO - Running: ['airflow', 'run', 'twitter_dag', 'twitter_aluraonline', '2021-08-04T09:00:00+00:00', '--job_id', '14', '--pool', 'default_pool', '--raw', '-sd', 'DAGS_FOLDER/twitter_dag.py', '--cfg_path', '/tmp/tmp3wue0giz']
[2021-08-10 15:42:57,195] {standard_task_runner.py:78} INFO - Job 14: Subtask twitter_aluraonline
[2021-08-10 15:42:57,218] {logging_mixin.py:112} INFO - Running <TaskInstance: twitter_dag.twitter_aluraonline 2021-08-04T09:00:00+00:00 [running]> on host SAFIRA-097.safira.local
[2021-08-10 15:42:57,229] {taskinstance.py:1150} ERROR - unexpected '%'
Traceback (most recent call last):
  File "/home/ibernardes/datapipeline/.env/lib/python3.7/site-packages/airflow/models/taskinstance.py", line 965, in _run_raw_task
    self.render_templates(context=context)
  File "/home/ibernardes/datapipeline/.env/lib/python3.7/site-packages/airflow/models/taskinstance.py", line 1424, in render_templates
    self.task.render_template_fields(context)
  File "/home/ibernardes/datapipeline/.env/lib/python3.7/site-packages/airflow/models/baseoperator.py", line 719, in render_template_fields
    self._do_render_template_fields(self, self.template_fields, context, jinja_env, set())
  File "/home/ibernardes/datapipeline/.env/lib/python3.7/site-packages/airflow/models/baseoperator.py", line 726, in _do_render_template_fields
    rendered_content = self.render_template(content, context, jinja_env, seen_oids)
  File "/home/ibernardes/datapipeline/.env/lib/python3.7/site-packages/airflow/models/baseoperator.py", line 755, in render_template
    return jinja_env.from_string(content).render(**context)
  File "/home/ibernardes/datapipeline/.env/lib/python3.7/site-packages/jinja2/environment.py", line 941, in from_string
    return cls.from_code(self, self.compile(source), globals, None)
  File "/home/ibernardes/datapipeline/.env/lib/python3.7/site-packages/jinja2/environment.py", line 638, in compile
    self.handle_exception(source=source_hint)
  File "/home/ibernardes/datapipeline/.env/lib/python3.7/site-packages/jinja2/environment.py", line 832, in handle_exception
    reraise(*rewrite_traceback_stack(source=source))
  File "/home/ibernardes/datapipeline/.env/lib/python3.7/site-packages/jinja2/_compat.py", line 28, in reraise
    raise value.with_traceback(tb)
  File "<unknown>", line 1, in template
jinja2.exceptions.TemplateSyntaxError: unexpected '%'
[2021-08-10 15:42:57,231] {taskinstance.py:1194} INFO - Marking task as FAILED. dag_id=twitter_dag, task_id=twitter_aluraonline, execution_date=20210804T090000, start_date=20210810T184257, end_date=20210810T184257
[2021-08-10 15:43:02,042] {local_task_job.py:102} INFO - Task exited with return code 1
